Workbook

Sheet Charts
A1: CHARTS — SALES ANALYSIS
A2: This sheet contains the three charts required in Main Task 9.

Sheet Dashboard
A1: SALES DASHBOARD — KEY INSIGHTS
A3: Total Sales | C3: Total Profit | E3: Total Orders | G3: Average Discount
A4: =Analysis!B3 | C4: =Analysis!B4 | E4: =Analysis!B5 | G4: =Analysis!B6
E22: Insights to review
E23: 1. Use the region chart to compare regional sales.
E24: 2. Use the product pie chart to compare product contribution.
E25: 3. Compare discount scenarios on the Analysis sheet.
E26: 4. Review the top 10 customers on the Analysis sheet.
E27: 5. Check monthly growth arrows for increases and decreases.
A30: For the full-size Bar, Line and Pie charts, open the 'Charts' sheet.

Sheet Dataset
A1: Order ID | B1: Order Date | C1: Customer | D1: Region | E1: Product | F1: Quantity | G1: Unit Price | H1: Discount | I1: Total Sales | J1: Cost | K1: Profit | L1: Timestamp
A2: 1 | B2: 46107 | C2: Customer 014 | D2: East | E2: Tablet | F2: 4 | G2: 23510.43 | H2: 0.1 | I2: =F2*G2 | J2: 73500.27 | K2: =I2*(1-H2)-J2 | L2: =NOW()
A3: 2 | B3: 46285 | C3: Customer 006 | D3: North | E3: Laptop | F3: 1 | G3: 58452.56 | H3: 0.12 | I3: =F3*G3 | J3: 41246.36 | K3: =I3*(1-H3)-J3 | L3: =NOW()
A4: 3 | B4: 46097 | C4: Customer 026 | D4: North | E4: Phone | F4: 6 | G4: 25437.08 | H4: 0.15 | I4: =F4*G4 | J4: 118151.21 | K4: =I4*(1-H4)-J4 | L4: =NOW()
A5: 4 | B5: 46231 | C5: Customer 020 | D5: East | E5: Laptop | F5: 3 | G5: 60481.79 | H5: 0.15 | I5: =F5*G5 | J5: 116698.76 | K5: =I5*(1-H5)-J5 | L5: =NOW()
A6: 5 | B6: 46211 | C6: Customer 001 | D6: North | E6: Laptop | F6: 1 | G6: 63703.35 | H6: 0.02 | I6: =F6*G6 | J6: 45269.23 | K6: =I6*(1-H6)-J6 | L6: =NOW()
A7: 6 | B7: 46305 | C7: Customer 024 | D7: South | E7: Headphones | F7: 4 | G7: 3255.77 | H7: 0.15 | I7: =F7*G7 | J7: 8171.04 | K7: =I7*(1-H7)-J7 | L7: =NOW()
A8: 7 | B8: 46143 | C8: Customer 003 | D8: North | E8: Phone | F8: 6 | G8: 30625.11 | H8: 0.15 | I8: =F8*G8 | J8: 141664.13 | K8: =I8*(1-H8)-J8 | L8: =NOW()
A9: 8 | B9: 46059 | C9: Customer 004 | D9: East | E9: Monitor | F9: 7 | G9: 13686.43 | H9: 0.08 | I9: =F9*G9 | J9: 77087.92 | K9: =I9*(1-H9)-J9 | L9: =NOW()
A10: 9 | B10: 46297 | C10: Customer 014 | D10: South | E10: Tablet | F10: 4 | G10: 22006.33 | H10: 0.08 | I10: =F10*G10 | J10: 72089.97 | K10: =I10*(1-H10)-J10 | L10: =NOW()
A11: 10 | B11: 46220 | C11: Customer 009 | D11: West | E11: Laptop | F11: 2 | G11: 62617.11 | H11: 0.1 | I11: =F11*G11 | J11: 77716.15 | K11: =I11*(1-H11)-J11 | L11: =NOW()
A12: 11 | B12: 46058 | C12: Customer 018 | D12: North | E12: Monitor | F12: 5 | G12: 13492.2 | H12: 0.12 | I12: =F12*G12 | J12: 43346.52 | K12: =I12*(1-H12)-J12 | L12: =NOW()
A13: 12 | B13: 46110 | C13: Customer 021 | D13: South | E13: Tablet | F13: 3 | G13: 23152.15 | H13: 0.08 | I13: =F13*G13 | J13: 46477 | K13: =I13*(1-H13)-J13 | L13: =NOW()
... A121: 120 | B121: 46146 | C121: Customer 022 | D121: East | E121: Tablet | F121: 7 | G121: 20657.43 | H121: 0.12 | I121: =F121*G121 | J121: 98774.15 | K121: =I121*(1-H121)-J121 | L121: =NOW()

Sheet Analysis
A1: MAIN TASKS — SALES ANALYSIS | F1: Customer List | G1: Total Purchase
A2: Task / Metric | B2: Result / Formula | C2: Formula or Method | D2: Notes | F2: Customer 001 | G2: =SUMIF(Dataset!$C$2:$C$121,F2,Dataset!$I$2:$I$121)
A3: Total Sales | B3: =SUM(Dataset!I2:I121) | C3: SUM of Total Sales | D3: Sales before discount | F3: Customer 002 | G3: =SUMIF(Dataset!$C$2:$C$121,F3,Dataset!$I$2:$I$121)
A4: Total Profit | B4: =SUM(Dataset!K2:K121) | C4: SUM of Profit | D4: After discount and cost | F4: Customer 003 | G4: =SUMIF(Dataset!$C$2:$C$121,F4,Dataset!$I$2:$I$121)
A5: Total Orders | B5: =COUNTA(Dataset!A2:A121) | C5: COUNTA | D5: Number of orders | F5: Customer 004 | G5: =SUMIF(Dataset!$C$2:$C$121,F5,Dataset!$I$2:$I$121)
A6: Average Discount | B6: =AVERAGE(Dataset!H2:H121) | C6: AVERAGE | D6: Average discount rate | F6: Customer 005 | G6: =SUMIF(Dataset!$C$2:$C$121,F6,Dataset!$I$2:$I$121)
F7: Customer 006 | G7: =SUMIF(Dataset!$C$2:$C$121,F7,Dataset!$I$2:$I$121)
F8: Customer 007 | G8: =SUMIF(Dataset!$C$2:$C$121,F8,Dataset!$I$2:$I$121)
A9: TOP 10 CUSTOMERS — TOTAL PURCHASE | F9: Customer 008 | G9: =SUMIF(Dataset!$C$2:$C$121,F9,Dataset!$I$2:$I$121)
A10: Rank | B10: Customer | C10: Total Purchase | F10: Customer 009 | G10: =SUMIF(Dataset!$C$2:$C$121,F10,Dataset!$I$2:$I$121)
A11: 1 | B11: =INDEX($F$2:$F$31,MATCH(LARGE($G$2:$G$31,A11),$G$2:$G$31,0)) | C11: =LARGE($G$2:$G$31,A11) | F11: Customer 010 | G11: =SUMIF(Dataset!$C$2:$C$121,F11,Dataset!$I$2:$I$121)
A12: 2 | B12: =INDEX($F$2:$F$31,MATCH(LARGE($G$2:$G$31,A12),$G$2:$G$31,0)) | C12: =LARGE($G$2:$G$31,A12) | F12: Customer 011 | G12: =SUMIF(Dataset!$C$2:$C$121,F12,Dataset!$I$2:$I$121)
A13: 3 | B13: =INDEX($F$2:$F$31,MATCH(LARGE($G$2:$G$31,A13),$G$2:$G$31,0)) | C13: =LARGE($G$2:$G$31,A13) | F13: Customer 012 | G13: =SUMIF(Dataset!$C$2:$C$121,F13,Dataset!$I$2:$I$121)
A14: 4 | B14: =INDEX($F$2:$F$31,MATCH(LARGE($G$2:$G$31,A14),$G$2:$G$31,0)) | C14: =LARGE($G$2:$G$31,A14) | F14: Customer 013 | G14: =SUMIF(Dataset!$C$2:$C$121,F14,Dataset!$I$2:$I$121)
A15: 5 | B15: =INDEX($F$2:$F$31,MATCH(LARGE($G$2:$G$31,A15),$G$2:$G$31,0)) | C15: =LARGE($G$2:$G$31,A15) | F15: Customer 014 | G15: =SUMIF(Dataset!$C$2:$C$121,F15,Dataset!$I$2:$I$121)
A16: 6 | B16: =INDEX($F$2:$F$31,MATCH(LARGE($G$2:$G$31,A16),$G$2:$G$31,0)) | C16: =LARGE($G$2:$G$31,A16) | F16: Customer 015 | G16: =SUMIF(Dataset!$C$2:$C$121,F16,Dataset!$I$2:$I$121)
A17: 7 | B17: =INDEX($F$2:$F$31,MATCH(LARGE($G$2:$G$31,A17),$G$2:$G$31,0)) | C17: =LARGE($G$2:$G$31,A17) | F17: Customer 016 | G17: =SUMIF(Dataset!$C$2:$C$121,F17,Dataset!$I$2:$I$121)
A18: 8 | B18: =INDEX($F$2:$F$31,MATCH(LARGE($G$2:$G$31,A18),$G$2:$G$31,0)) | C18: =LARGE($G$2:$G$31,A18) | F18: Customer 017 | G18: =SUMIF(Dataset!$C$2:$C$121,F18,Dataset!$I$2:$I$121)
A19: 9 | B19: =INDEX($F$2:$F$31,MATCH(LARGE($G$2:$G$31,A19),$G$2:$G$31,0)) | C19: =LARGE($G$2:$G$31,A19) | F19: Customer 018 | G19: =SUMIF(Dataset!$C$2:$C$121,F19,Dataset!$I$2:$I$121)
A20: 10 | B20: =INDEX($F$2:$F$31,MATCH(LARGE($G$2:$G$31,A20),$G$2:$G$31,0)) | C20: =LARGE($G$2:$G$31,A20) | F20: Customer 019 | G20: =SUMIF(Dataset!$C$2:$C$121,F20,Dataset!$I$2:$I$121)
F21: Customer 020 | G21: =SUMIF(Dataset!$C$2:$C$121,F21,Dataset!$I$2:$I$121)
F22: Customer 021 | G22: =SUMIF(Dataset!$C$2:$C$121,F22,Dataset!$I$2:$I$121)
A23: WHAT-IF ANALYSIS — DISCOUNT VS TOTAL PROFIT | F23: Customer 022 | G23: =SUMIF(Dataset!$C$2:$C$121,F23,Dataset!$I$2:$I$121)
A24: Discount Rate | B24: Estimated Total Profit | C24: Formula | F24: Customer 023 | G24: =SUMIF(Dataset!$C$2:$C$121,F24,Dataset!$I$2:$I$121)
A25: 0 | B25: =SUMPRODUCT(Dataset!$I$2:$I$121,1-A25)-SUM(Dataset!$J$2:$J$121) | C25: =SUMPRODUCT(Dataset!$I$2:$I$121,1-A25)-SUM(Dataset!$J$2:$J$121) | F25: Customer 024 | G25: =SUMIF(Dataset!$C$2:$C$121,F25,Dataset!$I$2:$I$121)
A26: 0.05 | B26: =SUMPRODUCT(Dataset!$I$2:$I$121,1-A26)-SUM(Dataset!$J$2:$J$121) | C26: =SUMPRODUCT(Dataset!$I$2:$I$121,1-A26)-SUM(Dataset!$J$2:$J$121) | F26: Customer 025 | G26: =SUMIF(Dataset!$C$2:$C$121,F26,Dataset!$I$2:$I$121)
A27: 0.1 | B27: =SUMPRODUCT(Dataset!$I$2:$I$121,1-A27)-SUM(Dataset!$J$2:$J$121) | C27: =SUMPRODUCT(Dataset!$I$2:$I$121,1-A27)-SUM(Dataset!$J$2:$J$121) | F27: Customer 026 | G27: =SUMIF(Dataset!$C$2:$C$121,F27,Dataset!$I$2:$I$121)
A28: 0.15 | B28: =SUMPRODUCT(Dataset!$I$2:$I$121,1-A28)-SUM(Dataset!$J$2:$J$121) | C28: =SUMPRODUCT(Dataset!$I$2:$I$121,1-A28)-SUM(Dataset!$J$2:$J$121) | F28: Customer 027 | G28: =SUMIF(Dataset!$C$2:$C$121,F28,Dataset!$I$2:$I$121)
A29: 0.2 | B29: =SUMPRODUCT(Dataset!$I$2:$I$121,1-A29)-SUM(Dataset!$J$2:$J$121) | C29: =SUMPRODUCT(Dataset!$I$2:$I$121,1-A29)-SUM(Dataset!$J$2:$J$121) | F29: Customer 028 | G29: =SUMIF(Dataset!$C$2:$C$121,F29,Dataset!$I$2:$I$121)
A30: 0.25 | B30: =SUMPRODUCT(Dataset!$I$2:$I$121,1-A30)-SUM(Dataset!$J$2:$J$121) | C30: =SUMPRODUCT(Dataset!$I$2:$I$121,1-A30)-SUM(Dataset!$J$2:$J$121) | F30: Customer 029 | G30: =SUMIF(Dataset!$C$2:$C$121,F30,Dataset!$I$2:$I$121)
F31: Customer 030 | G31: =SUMIF(Dataset!$C$2:$C$121,F31,Dataset!$I$2:$I$121)
A33: LINEAR REGRESSION — PROFIT VS SALES
A34: Measure | B34: Value / Formula | C34: Meaning
A35: Slope | B35: =SLOPE(Dataset!K2:K121,Dataset!I2:I121) | C35: Profit change relative to sales
A36: Intercept | B36: =INTERCEPT(Dataset!K2:K121,Dataset!I2:I121) | C36: Estimated profit at zero sales
A37: R-squared | B37: =RSQ(Dataset!K2:K121,Dataset!I2:I121) | C37: How much variation is explained
A38: Correlation | B38: =CORREL(Dataset!K2:K121,Dataset!I2:I121) | C38: Direction and strength of relationship
A41: DESCRIPTIVE STATISTICS
A42: Variable | B42: Mean | C42: Median | D42: Standard Deviation
A43: Total Sales | B43: =AVERAGE(Dataset!I2:I121) | C43: =MEDIAN(Dataset!I2:I121) | D43: =STDEV.S(Dataset!I2:I121)
...

Sheet Monthly Growth
A1: Month | B1: Total Sales | C1: Growth % | D1: Arrow
A2: 46023 | B2: =SUMIFS(Dataset!$I$2:$I$121,Dataset!$B$2:$B$121,">="&A2,Dataset!$B$2:$B$121,"<"&EDATE(A2,1)) | C2: 0 | D2: —
A3: 46054 | B3: =SUMIFS(Dataset!$I$2:$I$121,Dataset!$B$2:$B$121,">="&A3,Dataset!$B$2:$B$121,"<"&EDATE(A3,1)) | C3: =IFERROR(B3/B2-1,0) | D3: =IF(B3>B2,"↑",IF(B3<B2,"↓","→"))
A4: 46082 | B4: =SUMIFS(Dataset!$I$2:$I$121,Dataset!$B$2:$B$121,">="&A4,Dataset!$B$2:$B$121,"<"&EDATE(A4,1)) | C4: =IFERROR(B4/B3-1,0) | D4: =IF(B4>B3,"↑",IF(B4<B3,"↓","→"))
A5: 46113 | B5: =SUMIFS(Dataset!$I$2:$I$121,Dataset!$B$2:$B$121,">="&A5,Dataset!$B$2:$B$121,"<"&EDATE(A5,1)) | C5: =IFERROR(B5/B4-1,0) | D5: =IF(B5>B4,"↑",IF(B5<B4,"↓","→"))
A6: 46143 | B6: =SUMIFS(Dataset!$I$2:$I$121,Dataset!$B$2:$B$121,">="&A6,Dataset!$B$2:$B$121,"<"&EDATE(A6,1)) | C6: =IFERROR(B6/B5-1,0) | D6: =IF(B6>B5,"↑",IF(B6<B5,"↓","→"))
A7: 46174 | B7: =SUMIFS(Dataset!$I$2:$I$121,Dataset!$B$2:$B$121,">="&A7,Dataset!$B$2:$B$121,"<"&EDATE(A7,1)) | C7: =IFERROR(B7/B6-1,0) | D7: =IF(B7>B6,"↑",IF(B7<B6,"↓","→"))
A8: 46204 | B8: =SUMIFS(Dataset!$I$2:$I$121,Dataset!$B$2:$B$121,">="&A8,Dataset!$B$2:$B$121,"<"&EDATE(A8,1)) | C8: =IFERROR(B8/B7-1,0) | D8: =IF(B8>B7,"↑",IF(B8<B7,"↓","→"))
A9: 46235 | B9: =SUMIFS(Dataset!$I$2:$I$121,Dataset!$B$2:$B$121,">="&A9,Dataset!$B$2:$B$121,"<"&EDATE(A9,1)) | C9: =IFERROR(B9/B8-1,0) | D9: =IF(B9>B8,"↑",IF(B9<B8,"↓","→"))
A10: 46266 | B10: =SUMIFS(Dataset!$I$2:$I$121,Dataset!$B$2:$B$121,">="&A10,Dataset!$B$2:$B$121,"<"&EDATE(A10,1)) | C10: =IFERROR(B10/B9-1,0) | D10: =IF(B10>B9,"↑",IF(B10<B9,"↓","→"))
A11: 46296 | B11: =SUMIFS(Dataset!$I$2:$I$121,Dataset!$B$2:$B$121,">="&A11,Dataset!$B$2:$B$121,"<"&EDATE(A11,1)) | C11: =IFERROR(B11/B10-1,0) | D11: =IF(B11>B10,"↑",IF(B11<B10,"↓","→"))
A12: 46327 | B12: =SUMIFS(Dataset!$I$2:$I$121,Dataset!$B$2:$B$121,">="&A12,Dataset!$B$2:$B$121,"<"&EDATE(A12,1)) | C12: =IFERROR(B12/B11-1,0) | D12: =IF(B12>B11,"↑",IF(B12<B11,"↓","→"))
A13: 46357 | B13: =SUMIFS(Dataset!$I$2:$I$121,Dataset!$B$2:$B$121,">="&A13,Dataset!$B$2:$B$121,"<"&EDATE(A13,1)) | C13: =IFERROR(B13/B12-1,0) | D13: =IF(B13>B12,"↑",IF(B13<B12,"↓","→"))

Sheet Sales by Region-Product
A1: TOTAL SALES BY REGION AND PRODUCT
A3: Region / Product | B3: Laptop | C3: Phone | D3: Tablet | E3: Headphones | F3: Monitor | G3: Total
A4: West | B4: =SUMIFS(Dataset!$I$2:$I$121,Dataset!$D$2:$D$121,$A4,Dataset!$E$2:$E$121,B$3) | C4: =SUMIFS(Dataset!$I$2:$I$121,Dataset!$D$2:$D$121,$A4,Dataset!$E$2:$E$121,C$3) | D4: =SUMIFS(Dataset!$I$2:$I$121,Dataset!$D$2:$D$121,$A4,Dataset!$E$2:$E$121,D$3) | E4: =SUMIFS(Dataset!$I$2:$I$121,Dataset!$D$2:$D$121,$A4,Dataset!$E$2:$E$121,E$3) | F4: =SUMIFS(Dataset!$I$2:$I$121,Dataset!$D$2:$D$121,$A4,Dataset!$E$2:$E$121,F$3) | G4: =SUM(B4:F4)
A5: North | B5: =SUMIFS(Dataset!$I$2:$I$121,Dataset!$D$2:$D$121,$A5,Dataset!$E$2:$E$121,B$3) | C5: =SUMIFS(Dataset!$I$2:$I$121,Dataset!$D$2:$D$121,$A5,Dataset!$E$2:$E$121,C$3) | D5: =SUMIFS(Dataset!$I$2:$I$121,Dataset!$D$2:$D$121,$A5,Dataset!$E$2:$E$121,D$3) | E5: =SUMIFS(Dataset!$I$2:$I$121,Dataset!$D$2:$D$121,$A5,Dataset!$E$2:$E$121,E$3) | F5: =SUMIFS(Dataset!$I$2:$I$121,Dataset!$D$2:$D$121,$A5,Dataset!$E$2:$E$121,F$3) | G5: =SUM(B5:F5)
A6: South | B6: =SUMIFS(Dataset!$I$2:$I$121,Dataset!$D$2:$D$121,$A6,Dataset!$E$2:$E$121,B$3) | C6: =SUMIFS(Dataset!$I$2:$I$121,Dataset!$D$2:$D$121,$A6,Dataset!$E$2:$E$121,C$3) | D6: =SUMIFS(Dataset!$I$2:$I$121,Dataset!$D$2:$D$121,$A6,Dataset!$E$2:$E$121,D$3) | E6: =SUMIFS(Dataset!$I$2:$I$121,Dataset!$D$2:$D$121,$A6,Dataset!$E$2:$E$121,E$3) | F6: =SUMIFS(Dataset!$I$2:$I$121,Dataset!$D$2:$D$121,$A6,Dataset!$E$2:$E$121,F$3) | G6: =SUM(B6:F6)
A7: East | B7: =SUMIFS(Dataset!$I$2:$I$121,Dataset!$D$2:$D$121,$A7,Dataset!$E$2:$E$121,B$3) | C7: =SUMIFS(Dataset!$I$2:$I$121,Dataset!$D$2:$D$121,$A7,Dataset!$E$2:$E$121,C$3) | D7: =SUMIFS(Dataset!$I$2:$I$121,Dataset!$D$2:$D$121,$A7,Dataset!$E$2:$E$121,D$3) | E7: =SUMIFS(Dataset!$I$2:$I$121,Dataset!$D$2:$D$121,$A7,Dataset!$E$2:$E$121,E$3) | F7: =SUMIFS(Dataset!$I$2:$I$121,Dataset!$D$2:$D$121,$A7,Dataset!$E$2:$E$121,F$3) | G7: =SUM(B7:F7)
A8: Grand Total | B8: =SUM(B4:B7) | C8: =SUM(C4:C7) | D8: =SUM(D4:D7) | E8: =SUM(E4:E7) | F8: =SUM(F4:F7) | G8: =SUM(G4:G7)
